<?xml version="1.0" encoding="UTF-8"?>
<testng-results skipped="0" failed="2" ignored="0" total="2" passed="0">
  <reporter-output>
  </reporter-output>
  <suite name="Default suite" duration-ms="11239" started-at="2022-08-31T04:23:34Z" finished-at="2022-08-31T04:23:45Z">
    <groups>
    </groups>
    <test name="Default test" duration-ms="11239" started-at="2022-08-31T04:23:34Z" finished-at="2022-08-31T04:23:45Z">
      <class name="TestCases.capturesc">
        <test-method status="PASS" signature="before()[pri:0, instance:TestCases.capturesc@2ac273d3]" name="before" is-config="true" duration-ms="6845" started-at="2022-08-31T09:53:34Z" finished-at="2022-08-31T09:53:41Z">
          <reporter-output>
          </reporter-output>
        </test-method> <!-- before -->
        <test-method status="FAIL" signature="verifylabeltest()[pri:0, instance:TestCases.capturesc@2ac273d3]" name="verifylabeltest" duration-ms="42" started-at="2022-08-31T09:53:41Z" finished-at="2022-08-31T09:53:41Z">
          <exception class="java.lang.AssertionError">
            <message>
              <![CDATA[expected [1Login to Kite] but found [Login to Kite]]]>
            </message>
            <full-stacktrace>
              <![CDATA[java.lang.AssertionError: expected [1Login to Kite] but found [Login to Kite]
	at org.testng.Assert.fail(Assert.java:94)
	at org.testng.Assert.failNotEquals(Assert.java:513)
	at org.testng.Assert.assertEqualsImpl(Assert.java:135)
	at org.testng.Assert.assertEquals(Assert.java:116)
	at org.testng.Assert.assertEquals(Assert.java:190)
	at org.testng.Assert.assertEquals(Assert.java:200)
	at TestCases.capturesc.verifylabeltest(capturesc.java:46)
	at sun.reflect.NativeMethodAccessorImpl.invoke0(Native Method)
	at sun.reflect.NativeMethodAccessorImpl.invoke(Unknown Source)
	at sun.reflect.DelegatingMethodAccessorImpl.invoke(Unknown Source)
	at java.lang.reflect.Method.invoke(Unknown Source)
	at org.testng.internal.MethodInvocationHelper.invokeMethod(MethodInvocationHelper.java:104)
	at org.testng.internal.Invoker.invokeMethod(Invoker.java:645)
	at org.testng.internal.Invoker.invokeTestMethod(Invoker.java:851)
	at org.testng.internal.Invoker.invokeTestMethods(Invoker.java:1177)
	at org.testng.internal.TestMethodWorker.invokeTestMethods(TestMethodWorker.java:129)
	at org.testng.internal.TestMethodWorker.run(TestMethodWorker.java:112)
	at org.testng.TestRunner.privateRun(TestRunner.java:756)
	at org.testng.TestRunner.run(TestRunner.java:610)
	at org.testng.SuiteRunner.runTest(SuiteRunner.java:387)
	at org.testng.SuiteRunner.runSequentially(SuiteRunner.java:382)
	at org.testng.SuiteRunner.privateRun(SuiteRunner.java:340)
	at org.testng.SuiteRunner.run(SuiteRunner.java:289)
	at org.testng.SuiteRunnerWorker.runSuite(SuiteRunnerWorker.java:52)
	at org.testng.SuiteRunnerWorker.run(SuiteRunnerWorker.java:86)
	at org.testng.TestNG.runSuitesSequentially(TestNG.java:1293)
	at org.testng.TestNG.runSuitesLocally(TestNG.java:1218)
	at org.testng.TestNG.runSuites(TestNG.java:1133)
	at org.testng.TestNG.run(TestNG.java:1104)
	at org.testng.remote.AbstractRemoteTestNG.run(AbstractRemoteTestNG.java:132)
	at org.testng.remote.RemoteTestNG.initAndRun(RemoteTestNG.java:236)
	at org.testng.remote.RemoteTestNG.main(RemoteTestNG.java:81)
]]>
            </full-stacktrace>
          </exception> <!-- java.lang.AssertionError -->
          <reporter-output>
          </reporter-output>
        </test-method> <!-- verifylabeltest -->
        <test-method status="PASS" signature="exit(org.testng.ITestResult)[pri:0, instance:TestCases.capturesc@2ac273d3]" name="exit" is-config="true" duration-ms="950" started-at="2022-08-31T09:53:41Z" finished-at="2022-08-31T09:53:42Z">
          <params>
            <param index="0">
              <value>
                <![CDATA[[TestResult name=verifylabeltest status=FAILURE method=capturesc.verifylabeltest()[pri:0, instance:TestCases.capturesc@2ac273d3] output={null}]]]>
              </value>
            </param>
          </params>
          <reporter-output>
          </reporter-output>
        </test-method> <!-- exit -->
        <test-method status="PASS" signature="before()[pri:0, instance:TestCases.capturesc@2ac273d3]" name="before" is-config="true" duration-ms="2416" started-at="2022-08-31T09:53:42Z" finished-at="2022-08-31T09:53:44Z">
          <reporter-output>
          </reporter-output>
        </test-method> <!-- before -->
        <test-method status="FAIL" signature="verifytitleTest()[pri:0, instance:TestCases.capturesc@2ac273d3]" name="verifytitleTest" duration-ms="20" started-at="2022-08-31T09:53:44Z" finished-at="2022-08-31T09:53:44Z">
          <exception class="java.lang.AssertionError">
            <message>
              <![CDATA[title right or wrong? expected [1Kite - Zerodha's fast and elegant flagship trading platform] but found [Kite - Zerodha's fast and elegant flagship trading platform]]]>
            </message>
            <full-stacktrace>
              <![CDATA[java.lang.AssertionError: title right or wrong? expected [1Kite - Zerodha's fast and elegant flagship trading platform] but found [Kite - Zerodha's fast and elegant flagship trading platform]
	at org.testng.Assert.fail(Assert.java:94)
	at org.testng.Assert.failNotEquals(Assert.java:513)
	at org.testng.Assert.assertEqualsImpl(Assert.java:135)
	at org.testng.Assert.assertEquals(Assert.java:116)
	at org.testng.Assert.assertEquals(Assert.java:190)
	at TestCases.capturesc.verifytitleTest(capturesc.java:36)
	at sun.reflect.NativeMethodAccessorImpl.invoke0(Native Method)
	at sun.reflect.NativeMethodAccessorImpl.invoke(Unknown Source)
	at sun.reflect.DelegatingMethodAccessorImpl.invoke(Unknown Source)
	at java.lang.reflect.Method.invoke(Unknown Source)
	at org.testng.internal.MethodInvocationHelper.invokeMethod(MethodInvocationHelper.java:104)
	at org.testng.internal.Invoker.invokeMethod(Invoker.java:645)
	at org.testng.internal.Invoker.invokeTestMethod(Invoker.java:851)
	at org.testng.internal.Invoker.invokeTestMethods(Invoker.java:1177)
	at org.testng.internal.TestMethodWorker.invokeTestMethods(TestMethodWorker.java:129)
	at org.testng.internal.TestMethodWorker.run(TestMethodWorker.java:112)
	at org.testng.TestRunner.privateRun(TestRunner.java:756)
	at org.testng.TestRunner.run(TestRunner.java:610)
	at org.testng.SuiteRunner.runTest(SuiteRunner.java:387)
	at org.testng.SuiteRunner.runSequentially(SuiteRunner.java:382)
	at org.testng.SuiteRunner.privateRun(SuiteRunner.java:340)
	at org.testng.SuiteRunner.run(SuiteRunner.java:289)
	at org.testng.SuiteRunnerWorker.runSuite(SuiteRunnerWorker.java:52)
	at org.testng.SuiteRunnerWorker.run(SuiteRunnerWorker.java:86)
	at org.testng.TestNG.runSuitesSequentially(TestNG.java:1293)
	at org.testng.TestNG.runSuitesLocally(TestNG.java:1218)
	at org.testng.TestNG.runSuites(TestNG.java:1133)
	at org.testng.TestNG.run(TestNG.java:1104)
	at org.testng.remote.AbstractRemoteTestNG.run(AbstractRemoteTestNG.java:132)
	at org.testng.remote.RemoteTestNG.initAndRun(RemoteTestNG.java:236)
	at org.testng.remote.RemoteTestNG.main(RemoteTestNG.java:81)
]]>
            </full-stacktrace>
          </exception> <!-- java.lang.AssertionError -->
          <reporter-output>
          </reporter-output>
        </test-method> <!-- verifytitleTest -->
        <test-method status="PASS" signature="exit(org.testng.ITestResult)[pri:0, instance:TestCases.capturesc@2ac273d3]" name="exit" is-config="true" duration-ms="949" started-at="2022-08-31T09:53:44Z" finished-at="2022-08-31T09:53:45Z">
          <params>
            <param index="0">
              <value>
                <![CDATA[[TestResult name=verifytitleTest status=FAILURE method=capturesc.verifytitleTest()[pri:0, instance:TestCases.capturesc@2ac273d3] output={null}]]]>
              </value>
            </param>
          </params>
          <reporter-output>
          </reporter-output>
        </test-method> <!-- exit -->
      </class> <!-- TestCases.capturesc -->
    </test> <!-- Default test -->
  </suite> <!-- Default suite -->
</testng-results>
